<mujoco model="upper_limb_exo">
    <option gravity="0 0 -9.81" />
    <compiler angle="degree" meshdir="meshes/" autolimits="true" />


    <option timestep="0.001"></option>     <!-- time step for simulations  -->

    <default>
        <geom type="mesh" />
    </default>

    <default>
        <default class="visual">
            <geom contype="0" conaffinity="0" group="0" density="0" rgba="0.5 0.5 0.5 1" />
        </default>
        <default class="transparent">
            <geom contype="0" conaffinity="0" group="0" density="0" rgba="0.5 0.5 0.5 0.3" />
        </default>
    </default>

    <default>
        <default class="AK7010_actuator">
            <joint damping="0.015" armature="0.00414" frictionloss="0.5" />
        </default>

        <default class="AK109_actuator">
            <joint damping="0.03" armature="0.00812" frictionloss="0.5" />
        </default>

        <default class="AK606_actuator">
            <joint damping="0.02" armature="0.00088" frictionloss="0.25" />
        </default>
    </default>

    <!--   Fusion outputs meshes with mm units by default, but must be converted to m in MuJoCo, hence
    the scaling   -->
    <asset>
        <mesh name="link0_AK10_9" file="link0_AK10_9.stl" scale="0.001 0.001 0.001" />
        <mesh name="link1_upper_arm" file="link1_upper_arm.stl" scale="0.001 0.001 0.001" />
        <mesh name="link2_upper_arm" file="link2_upper_arm.stl" scale="0.001 0.001 0.001" />
        <mesh name="link3_lower_arm" file="link3_lower_arm.stl" scale="0.001 0.001 0.001" />
        <mesh name="dummy_upper_arm" file="dummy_upper_arm.stl" scale="0.001 0.001 0.001" />
        <mesh name="dummy_lower_arm" file="dummy_lower_arm.stl" scale="0.001 0.001 0.001" />
    </asset>
    <visual>
        <headlight diffuse="0.6 0.6 0.6" ambient="0.3 0.3 0.3" specular="0 0 0" />
        <rgba haze="0.15 0.25 0.35 1" />
        <global azimuth="-130" elevation="-20" />
    </visual>

    <asset>
        <texture builtin="gradient" height="100" rgb1=".4 .5 .6" rgb2="0 0 0" type="skybox"
            width="100" />
        <texture name="texplane" type="2d" builtin="checker" rgb1=".2 .3 .4" rgb2=".1 0.15 0.2"
            width="100" height="100" />
        <material name="MatPlane" reflectance="0.1" texture="texplane" texrepeat="1 1"
            texuniform="true" />
    </asset>


    <worldbody>
        <geom name="ground" pos="0 0 0" size="5 5 0.05" type="plane" material="MatPlane"
            friction="1 1 0.1" condim="3" conaffinity="1" contype="1" group="2" rgba="0.8 0.9 0.8 1" />

        <light cutoff="1000" diffuse="1 1 1" dir="-0 0 -1.3" directional="true" exponent="1"
            pos="0 0 1.3" specular=".1 .1 .1" castshadow="false" />

        <!--   Link0_AK10-9_motor_fixed -->
        <body name="link0_AK10_9" pos="0 0 0.7" euler="90 0 0">
            <geom type="mesh" class="visual" mesh="link0_AK10_9" rgba="0 0 0 1" />
            <inertial pos="0 0 0" mass="0.8"
                fullinertia="1.338E-5 1.019E-5 6.278E-6 0 0 0" />
            <!--   link1_upper_arm -->
            <body name="link1_upper_arm" pos="0 0 0" euler="180 0 0">
                <geom type="mesh" class="visual" mesh="link1_upper_arm" rgba="0.6 0 0 1" />
                <inertial pos="-0.008E-3 82.868E-3 0.778E-3" mass="526.976E-3"
                    fullinertia="8.079E-4 3.017E-4 9.044E-4 52.342E-9 94.758E-9 38735.363E-9" />
                    <!-- IXX, IYY, IZZ, IXY, IXZ, IYZ-->
                <joint type="hinge" name="shoulder_pitch" axis="0 0 1" pos="0 0 0" range="-150 0"
                    class="AK109_actuator" />


                <!--   link2_upper_arm -->
                <body name="link2_upper_arm" pos="0 113.23E-3 84E-3" euler="90 0 0">
                    <geom type="mesh" class="visual" mesh="link2_upper_arm" rgba="0.3 0.4 0 1" />
                    <inertial pos="-0.027E-3 -79.133E-3 -145.119E-3" mass="1.247087"
                        fullinertia="7.413E-3 7.163E-3 1.591E-3 5466.478E-9 5065.844E-9 -1.911E-3" />
                    <joint type="hinge" name="shoulder_yaw" axis="0 0 1" pos="0 0 0" range="-40 40"
                        class="AK109_actuator" />
                    <!--   dummy upper arm   complete -->
                    <body name="dummy_upper_arm" pos="0 0 -25E-3" euler="0 0 0">
                        <geom type="mesh" class="visual" mesh="dummy_upper_arm" rgba="1 0.75 0.8 1" />
                        <inertial pos="0 0 0" mass="2.488242"
                            fullinertia="2.707E-2 2.707E-2 1.931E-3 0 0 0" />
                    </body>

                    <body name="link3_lower_arm" pos="0 -74E-3 -193.727E-3" euler="90 0 -90">
                        <geom type="mesh" class="visual" mesh="link3_lower_arm" rgba="0.3 0 0.6 1"/>
                        <inertial pos="115.097E-3 0.129E-3 -16.176E-3" mass="0.309307"
                            fullinertia="1.017E-4 1.605E-3 1.619E-3 783.496E-9 -22863.499E-9 732.688E-9" />
                        <joint type="hinge" name="elbow" axis="0 0 -1" pos="0 0 0" range="-150 0"
                            class="AK109_actuator" />

                        <!--   dummy lower arm-->
                        <body name="dummy_lower_arm" pos="131.273E-3 0 -74E-3" euler="90 90 0">
                            <geom type="mesh" class="visual" mesh="dummy_lower_arm"
                                rgba="1 0.75 0.8 1" />
                            <inertial pos="-3.440E-12 0 0" mass="1.998991"
                                fullinertia="2.331E-2 2.331E-2 1.086E-3 6.394E-19 2.840E-14 0" />
                        </body>
                    </body>
                </body>
            </body>
        </body>
    </worldbody>

    <actuator>
        <motor name="shoulder_pitch_m" joint="shoulder_pitch" ctrlrange="-48 48" />
        <motor name="shoulder_yaw_m" joint="shoulder_yaw" ctrlrange="-15 15" />
        <motor name="elbow_m" joint="elbow" ctrlrange="-18 18" />
    </actuator>

</mujoco>
